<?xml version="1.0"?>
<robot xmlns:xacro="http://www.ros.org/wiki/xacro" >

    <xacro:include filename="inertial_macros.xacro"/>
    

    <material name="white">
        <color rgba="1 1 1 1" />
    </material>

    <material name="orange">
        <color rgba="1 0.3 0.1 1"/>
    </material>

    <material name="blue">
        <color rgba="0.2 0.2 1 1"/>
    </material>

    <material name="black">
        <color rgba="0 0 0 1"/>
    </material>
    
    
    <material name="red">
        <color rgba="1 0 0 1"/>
    </material>

    <material name="yellow">
        <color rgba="1 1 0 1"/>
    </material>
    
    <material name="green">
        <color rgba="0 1 0 1"/>
    </material> 
    
    <material name="cyan">
        <color rgba="0 1 1 1"/>
    </material>   
    

    <!-- BASE LINK -->

    <link name="base_link">

    </link>
    <joint name="base_footprint_joint" type="fixed">
        <parent link="base_link"/>
        <child link="base_footprint"/>
        <origin xyz="0 0 0" rpy="0 0 0"/>
    </joint>

    <link name="base_footprint">
    </link>


    <!-- CHASSIS LINK -->

    <joint name="chassis_joint" type="fixed">
        <parent link="base_link"/>
        <child link="chassis"/>
        <origin xyz="-0.1 0 0"/>
    </joint>

    <link name="chassis">
        <visual>
            <origin xyz="0.15 0 0.075"/>
            <geometry>
                <box size="0.5 0.3 0.15"/>
            </geometry>
            <material name="red"/>
        </visual>
        <collision>
            <origin xyz="0.15 0 0.075"/>
            <geometry>
                <box size="0.5 0.3 0.15"/>
            </geometry>
        </collision>
        <xacro:inertial_box mass="0.5" x="0.5" y="0.3" z="0.15">
            <origin xyz="0.15 0 0.075" rpy="0 0 0"/>
        </xacro:inertial_box>
    </link>

    <gazebo reference="chassis">
        <material> Gazebo/Orange</material>
    </gazebo>
    
    <!-- FRONT LEFT WHEEL LINK -->

    <joint name="front_left_steering_joint" type="continuous">
        <parent link="base_link"/>
        <child link="front_left_streeing"/>
        <!--limit effort="5" lower="-2.1" upper="2.1" velocity="6.28"/-->
        <origin xyz="-0.090 0.175 0" rpy="${pi/2} 0 0" />
        <axis xyz="0 0 1"/>
    </joint>

    <link name="front_left_streeing">
        <visual>
            <geometry>
                <cylinder radius="0.05" length="0.04"/>
            </geometry>
            <material name="black"/>
        </visual>
        <collision>
            <geometry>
                <cylinder radius="0.05" length="0.04"/>
            </geometry>
        </collision>
        <xacro:inertial_cylinder mass="0.1" length="0.01" radius="0.01">
            <origin xyz="0 0 0" rpy="0 0 0"/>
        </xacro:inertial_cylinder>
    </link>
    
    <gazebo reference="front_left_streeing">
        <material> Gazebo/Blue</material>
    </gazebo>
    
    
    

    <!-- FRONT RIGHT WHEEL LINK -->
    
     <joint name="front_right_steering_joint" type="continuous">
        <parent link="base_link"/>
        <child link="front_right_steering"/>
        <!--limit effort="5" lower="-2.1" upper="2.1" velocity="6.28"/-->
        <origin xyz="-0.090 -0.175 0" rpy="${pi/2} 0 0" />
        <axis xyz="0 0 -1"/>
    </joint>

    <link name="front_right_steering">
        <visual>
            <geometry>
                <cylinder radius="0.05" length="0.04"/>
            </geometry>
            <material name="black"/>
        </visual>
        <collision>
            <geometry>
                <cylinder radius="0.05" length="0.04"/>
            </geometry>
        </collision>
        <xacro:inertial_cylinder mass="0.1" length="0.01" radius="0.01">
            <origin xyz="0 0 0" rpy="0 0 0"/>
        </xacro:inertial_cylinder>
    </link>
   
    <gazebo reference="front_right_steering">
        <material> Gazebo/Blue</material>
    </gazebo>

    <!-- ADDITIONAL WHEEL LINKS -->

    <!-- REAR RIGHT WHEEL LINK -->

    <joint name="rear_right_wheel_joint" type="continuous">
        <parent link="base_link"/>
        <child link="rear_right_wheel"/>
        <origin xyz="0.180 -0.175 0" rpy="${pi/2} 0 0"/>
        <axis xyz="0 0 -1"/>
    </joint>

    <link name="rear_right_wheel">
        <visual>
            <geometry>
                <cylinder radius="0.05" length="0.04"/>
            </geometry>
            <material name="black"/>
        </visual>
        <collision>
            <geometry>
                <cylinder radius="0.05" length="0.04"/>
            </geometry>
        </collision>
        <xacro:inertial_cylinder mass="0.1" length="0.04" radius="0.05">
            <origin xyz="0 0 0" rpy="0 0 0"/>
        </xacro:inertial_cylinder>
    </link>

     <gazebo reference="rear_right_wheel">
        <material> Gazebo/Blue</material>
    </gazebo>   

    <!-- REAR LEFT WHEEL LINK -->

    <joint name="rear_left_wheel_joint" type="continuous">
        <parent link="base_link"/>
        <child link="rear_left_wheel"/>
        <origin xyz="0.180 0.175 0" rpy="${pi/2} 0 0"/>
        <axis xyz="0 0 1"/>
    </joint>

    <link name="rear_left_wheel">
        <visual>
            <geometry>
                <cylinder radius="0.05" length="0.04"/>
            </geometry>
            <material name="black"/>
        </visual>
        <collision>
            <geometry>
                <cylinder radius="0.05" length="0.04"/>
            </geometry>
        </collision>
        <xacro:inertial_cylinder mass="0.1" length="0.04" radius="0.05">
            <origin xyz="0 0 0" rpy="0 0 0"/>
        </xacro:inertial_cylinder>
    </link>

     <gazebo reference="rear_left_wheel">
        <material> Gazebo/Blue</material>
        
    </gazebo>    
    
    <!-- ARM -->
	<link name="arm_base">
   		<visual>
     			<geometry>
       				<box size="0.1 .1 .1"/>
     			</geometry>
			<origin rpy="0 0 0" xyz="0 0 0.1"/>
			<material name="green">
			</material>
   		</visual>
		<collision>
			<geometry>
       				<box size="0.1 .1 .1"/>
			</geometry>
		</collision>
       		<xacro:inertial_box mass="0.05" x="0.1" y="0.1" z="0.1">
         	<origin xyz="0 0 0.1" rpy="0 0 0"/>
        	</xacro:inertial_box>
 	</link>

	<joint name="base_to_arm_base" type="fixed">
		<parent link="chassis"/>
		<child link="arm_base"/>
		<axis xyz="0 0 1"/>
		<origin xyz="0 0 0"/>
		<limit effort ="1000.0" lower="-0.32" upper="0.32" velocity="0.5"/>
		
	</joint>


	<link name="arm_1">
   		<visual>
     			<geometry>
       				<box size="0.05 .05 0.3"/>
     			</geometry>
			<origin rpy="0 0 0" xyz="0 0 0.15"/>
			<material name="yellow">
			</material>
   		</visual>
		<collision>
			<geometry>
       				<box size="0.05 .05 0.3"/>
			</geometry>
		</collision>
        	<xacro:inertial_box mass="0.0005" x="0.05" y="0.05" z="0.3">
            	<origin xyz="0 0 0.15" rpy="0 0 0"/>
        	</xacro:inertial_box>
 	</link>

	<joint name="arm_1_to_arm_base" type="fixed">
		<parent link="arm_base"/>
		<child link="arm_1"/>
		<axis xyz="0 0 1"/>
		<origin xyz="0 0 0.15"/>
		<limit effort ="1000.0" lower="-0.40" upper="0.40" velocity="0.5"/>
	</joint>


	<link name="arm_2">
   		<visual>
     			<geometry>
       				<box size="0.05 0.05 0.3"/>
     			</geometry>
			<origin rpy="0 0 0" xyz="0.0 0.055 0.095"/>
			<material name="yellow">
			</material>
   		</visual>
		<collision>
			<geometry>
       				<box size="0.05 .05 0.3"/>
			</geometry>
		</collision>
        	<xacro:inertial_box mass="0.0005" x="0.05" y="0.05" z="0.3">
            	<origin xyz="0.0 0.055 0.095" rpy="0 0 0"/>
        	</xacro:inertial_box>
 	</link>

	<joint name="arm_2_to_arm_1" type="revolute">
		<parent link="arm_1"/>
		<child link="arm_2"/>
		<axis xyz="0 1 0"/>
		<origin xyz="0.0 0 0.3"/>
		<limit effort ="1000.0" lower="-1.06" upper="-1.05" velocity="0.5"/>
	</joint>
	
	<link name="arm_3">
   		<visual>
     			<geometry>
       				<box size="0.05 0.05 0.3"/>
     			</geometry>
			<origin rpy="0 0 0" xyz="0.0 0.09 0.12"/>
			<material name="yellow">
			</material>
   		</visual>
		<collision>
			<geometry>
       				<box size="0.05 .05 0.3"/>
			</geometry>
		</collision>
        	<xacro:inertial_box mass="0.0005" x="0.05" y="0.05" z="0.3">
            	<origin xyz="0.0 0.09 0.12" rpy="0 0 0"/>
        	</xacro:inertial_box>
 	</link>

	<joint name="arm_3_to_arm_2" type="revolute">
		<parent link="arm_2"/>
		<child link="arm_3"/>
		<axis xyz="0 1 0"/>
		<origin xyz="0 0.022 0.2"/>
		<limit effort ="1000.0" lower="-0.63" upper="-0.62" velocity="0.5"/>
	</joint>
	
</robot>

<!--link name="camera_link">
    <visual>
        <geometry>
            <box size="0.08 0.08 0.08"/>
        </geometry>
        <material name="orange"/>
    </visual>
    <collision>
        <geometry>
            <box size="0.1 0.1 0.1"/>
        </geometry>
    </collision>
    <xacro:default_inertial mass="0.01"/>
</link>
<joint name="camera_joint" type="continuous">
    <parent link="arm_3"/>
    <child link="camera_link"/>
    <axis xyz="1 0 0"/>
    <origin xyz="0.0 0.09 0.31"/>
    <limit effort="1000.0" lower="-2.5" upper="2.5" velocity="0.5"/>
</joint>


<link name="camera_lens">
    <visual>
        <geometry>
            <cylinder radius="0.03" length="0.025"/>
        </geometry>
        <material name="cyan"/>
    </visual>
    <collision>
        <geometry>
            <cylinder radius="0.01" length="0.02"/>
        </geometry>
    </collision>
    <xacro:default_inertial mass="0.005"/>
</link>

<joint name="cameralens_joint" type="fixed">
    <parent link="camera_link"/>
    <child link="camera_lens"/>
    <axis xyz="0 1 0"/>
    <origin xyz="0.0 0 0.05"/>
    <limit effort="1000.0" lower="-2.5" upper="2.5" velocity="0.5"/>
</joint-->


